<?xml version="1.0" ?>
<!-- =================================================================================== -->
<!-- |    This document was autogenerated by xacro from kuroko.xacro                   | -->
<!-- |    EDITING THIS FILE BY HAND IS NOT RECOMMENDED                                 | -->
<!-- =================================================================================== -->
<robot name="kuroko">
  <!-- 
  <xacro:include filename="$(find kuroko_description)/xacro/kuroko/parts/leg_l.xacro"/>
  <xacro:include filename="$(find kuroko_description)/xacro/kuroko/transmission/leg_l.gazebo"/>-->
  <link name="root_link"/>
  <joint name="root_joint" type="fixed">
    <parent link="root_link"/>
    <child link="chest"/>
    <origin rpy="0 0 0" xyz="0 0 0"/>
  </joint>
  <!-- chest -->
  <link name="chest">
    <visual>
      <origin rpy="0 0 0" xyz="0 0 0"/>
      <geometry>
        <mesh filename="package://kuroko_description/meshes/kuroko/obj/chest.obj"/>
      </geometry>
    </visual>
    <collision>
      <origin rpy="0 0 0" xyz="0 0 0.057"/>
      <geometry>
        <box size="0.1 0.204 0.114"/>
      </geometry>
    </collision>
    <inertial>
      <origin rpy="0 0 0" xyz="0 0 0.057"/>
      <mass value="0.991"/>
      <inertia ixx="0.004510040999999999" ixy="0.0" ixz="0.0" iyy="0.0018990863333333335" iyz="0.0" izz="0.0042626213333333334"/>
    </inertial>
  </link>
  <!-- Joint1 -->
  <joint name="waist_joint" type="revolute">
    <parent link="chest"/>
    <child link="waist"/>
    <origin rpy="0 0 0" xyz="0 0 0"/>
    <axis xyz="0 0 -1"/>
    <limit effort="1000.0" lower="-3.1" upper="3.1" velocity="10.0"/>
    <dynamics damping="0.0" friction="0.0"/>
  </joint>
  <!-- waist -->
  <link name="waist">
    <visual>
      <origin rpy="0 0 0" xyz="0 0 0"/>
      <geometry>
        <mesh filename="package://kuroko_description/meshes/kuroko/obj/waist.obj"/>
      </geometry>
    </visual>
    <collision>
      <origin rpy="0 0 0" xyz="0.00125 0 -0.04875"/>
      <geometry>
        <box size="0.0705 0.0325 0.0975"/>
      </geometry>
    </collision>
    <inertial>
      <origin rpy="0 0 0" xyz="0.00125 0 -0.04875"/>
      <mass value="0.337"/>
      <inertia ixx="0.00029663020833333337" ixy="0.0" ixz="0.0" iyy="0.00040654837500000003" iyz="0.0" izz="0.00016924420833333329"/>
    </inertial>
  </link>
  <gazebo reference="chest">
    <kp>1000000.0</kp>
    <kd>100.0</kd>
    <mu1>0.1</mu1>
    <maxVel>10.0</maxVel>
    <minDepth>0.0001</minDepth>
    <maxContacts>6</maxContacts>
    <selfCollide>false</selfCollide>
    <dampingFactor>0</dampingFactor>
  </gazebo>
  <gazebo reference="waist_joint">
    <implicitSpringDamper>1</implicitSpringDamper>
  </gazebo>
  <transmission name="waist_joint_trans">
    <type>transmission_interface/SimpleTransmission</type>
    <joint name="waist_joint">
      <hardwareInterface>hardware_interface/PositionJointInterface</hardwareInterface>
    </joint>
    <actuator name="waist_joint_motor">
      <hardwareInterface>hardware_interface/PositionJointInterface</hardwareInterface>
      <mechanicalReduction>1</mechanicalReduction>
    </actuator>
  </transmission>
  <gazebo reference="waist">
    <kp>1000000.0</kp>
    <kd>100.0</kd>
    <mu1>0.1</mu1>
    <maxVel>10.0</maxVel>
    <minDepth>0.0001</minDepth>
    <maxContacts>6</maxContacts>
    <selfCollide>false</selfCollide>
    <dampingFactor>0</dampingFactor>
  </gazebo>
  <!-- Link conencts from body. Shoulder first. -->
  <joint name="shoulder_r_joint" type="revolute">
    <parent link="chest"/>
    <child link="shoulder_r"/>
    <origin rpy="0 0 0" xyz="0 -0.108 0.01275"/>
    <axis xyz="0 -1 0"/>
    <limit effort="1000.0" lower="-3.1" upper="3.1" velocity="10.0"/>
    <dynamics damping="0.0" friction="0.0"/>
  </joint>
  <link name="shoulder_r">
    <visual>
      <origin rpy="0 0 0" xyz="0 0 0"/>
      <geometry>
        <mesh filename="package://kuroko_description/meshes/kuroko/obj/shoulder_r.obj"/>
      </geometry>
    </visual>
    <collision>
      <origin rpy="0 0 0" xyz="0 -0.0205 0"/>
      <geometry>
        <box size="0.042 0.041 0.04"/>
      </geometry>
    </collision>
    <inertial>
      <origin rpy="0 0 0" xyz="0 -0.0205 0"/>
      <mass value="0.022"/>
      <inertia ixx="1e-05" ixy="0.0" ixz="0.0" iyy="1e-05" iyz="0.0" izz="1e-05"/>
    </inertial>
  </link>
  <joint name="arm_r_joint" type="revolute">
    <parent link="shoulder_r"/>
    <child link="arm_r"/>
    <origin rpy="0 0 0" xyz="0 -0.028 0"/>
    <axis xyz="-1 0 0"/>
    <limit effort="1000.0" lower="-3.1" upper="3.1" velocity="10.0"/>
    <dynamics damping="0.0" friction="0.0"/>
  </joint>
  <link name="arm_r">
    <visual>
      <origin rpy="0 0 0" xyz="0 0 0"/>
      <geometry>
        <mesh filename="package://kuroko_description/meshes/kuroko/obj/arm_r.obj"/>
      </geometry>
    </visual>
    <collision>
      <origin rpy="0 0 0" xyz="0 -0.0385 -0.02575"/>
      <geometry>
        <box size="0.0285 0.1045 0.08"/>
      </geometry>
    </collision>
    <inertial>
      <origin rpy="0 0 0" xyz="0 -0.0385 -0.02575"/>
      <mass value="0.342"/>
      <inertia ixx="0.000493627125" ixy="0.0" ixz="0.0" iyy="0.000205549125" iyz="0.0" izz="0.00033437625000000003"/>
    </inertial>
  </link>
  <joint name="scissor_rf_joint" type="revolute">
    <parent link="arm_r"/>
    <child link="scissor_rf"/>
    <origin rpy="0 0 0" xyz="0 -0.0265 -0.0545"/>
    <axis xyz="0 -1 0"/>
    <limit effort="1000.0" lower="-3.1" upper="3.1" velocity="10.0"/>
    <dynamics damping="0.0" friction="0.0"/>
  </joint>
  <link name="scissor_rf">
    <visual>
      <origin rpy="0 0 0" xyz="0 0 0"/>
      <geometry>
        <mesh filename="package://kuroko_description/meshes/kuroko/obj/scissor_rf.obj"/>
      </geometry>
    </visual>
    <collision>
      <origin rpy="0 0 0" xyz="0.0043 0 -0.104"/>
      <geometry>
        <box size="0.01085 0.058 0.208"/>
      </geometry>
    </collision>
    <collision>
      <origin rpy="0 0 0" xyz="-0.0206 0 -0.201"/>
      <geometry>
        <box size="0.039 0.058 0.014"/>
      </geometry>
    </collision>
    <inertial>
      <origin rpy="0 0 0" xyz="0.0043 0 -0.104"/>
      <mass value="0.032"/>
      <inertia ixx="0.00012434133333333333" ixy="0.0" ixz="0.0" iyy="0.00012053333333333334" iyz="0.0" izz="1.4133333333333334e-05"/>
    </inertial>
  </link>
  <joint name="scissor_rr_joint" type="revolute">
    <parent link="arm_r"/>
    <child link="scissor_rr"/>
    <origin rpy="0 0 0" xyz="0 -0.0265 -0.0545"/>
    <axis xyz="0 1 0"/>
    <limit effort="1000.0" lower="-3.1" upper="3.1" velocity="10.0"/>
    <dynamics damping="0.0" friction="0.0"/>
  </joint>
  <link name="scissor_rr">
    <visual>
      <origin rpy="0 0 0" xyz="0 0 0"/>
      <geometry>
        <mesh filename="package://kuroko_description/meshes/kuroko/obj/scissor_rr.obj"/>
      </geometry>
    </visual>
    <collision>
      <origin rpy="0 0 0" xyz="-0.0043 0 -0.1"/>
      <geometry>
        <box size="0.01085 0.044 0.2"/>
      </geometry>
    </collision>
    <collision>
      <origin rpy="0 0 0" xyz="0.0206 0 -0.193"/>
      <geometry>
        <box size="0.039 0.044 0.014"/>
      </geometry>
    </collision>
    <inertial>
      <origin rpy="0 0 0" xyz="-0.0043 0 -0.1"/>
      <mass value="0.031"/>
      <inertia ixx="0.00010833466666666668" ixy="0.0" ixz="0.0" iyy="0.00010833466666666668" iyz="0.0" izz="1.0002666666666667e-05"/>
    </inertial>
  </link>
  <gazebo reference="shoulder_r_joint">
    <implicitSpringDamper>1</implicitSpringDamper>
  </gazebo>
  <transmission name="shoulder_r_joint_trans">
    <type>transmission_interface/SimpleTransmission</type>
    <joint name="shoulder_r_joint">
      <hardwareInterface>hardware_interface/PositionJointInterface</hardwareInterface>
    </joint>
    <actuator name="shoulder_r_joint_motor">
      <hardwareInterface>hardware_interface/PositionJointInterface</hardwareInterface>
      <mechanicalReduction>1</mechanicalReduction>
    </actuator>
  </transmission>
  <gazebo reference="shoulder_r">
    <kp>1000000.0</kp>
    <kd>100.0</kd>
    <mu1>0.0</mu1>
    <maxVel>10.0</maxVel>
    <minDepth>0.0001</minDepth>
    <maxContacts>6</maxContacts>
    <selfCollide>false</selfCollide>
    <dampingFactor>0</dampingFactor>
  </gazebo>
  <!-- Link conencts from body. Shoulder first. -->
  <joint name="shoulder_l_joint" type="revolute">
    <parent link="chest"/>
    <child link="shoulder_l"/>
    <origin rpy="0 0 0" xyz="0 0.108 0.01275"/>
    <axis xyz="0 1 0"/>
    <limit effort="1000.0" lower="-3.1" upper="3.1" velocity="10.0"/>
    <dynamics damping="0.0" friction="0.0"/>
  </joint>
  <link name="shoulder_l">
    <visual>
      <origin rpy="0 0 0" xyz="0 0 0"/>
      <geometry>
        <mesh filename="package://kuroko_description/meshes/kuroko/obj/shoulder_l.obj"/>
      </geometry>
    </visual>
    <collision>
      <origin rpy="0 0 0" xyz="0 0.0205 0"/>
      <geometry>
        <box size="0.042 0.041 0.04"/>
      </geometry>
    </collision>
    <inertial>
      <origin rpy="0 0 0" xyz="0 0.0205 0"/>
      <mass value="0.022"/>
      <inertia ixx="1e-05" ixy="0.0" ixz="0.0" iyy="1e-05" iyz="0.0" izz="1e-05"/>
    </inertial>
  </link>
  <joint name="arm_l_joint" type="revolute">
    <parent link="shoulder_l"/>
    <child link="arm_l"/>
    <origin rpy="0 0 0" xyz="0 0.028 0"/>
    <axis xyz="-1 0 0"/>
    <limit effort="1000.0" lower="-3.1" upper="3.1" velocity="10.0"/>
    <dynamics damping="0.0" friction="0.0"/>
  </joint>
  <link name="arm_l">
    <visual>
      <origin rpy="0 0 0" xyz="0 0 0"/>
      <geometry>
        <mesh filename="package://kuroko_description/meshes/kuroko/obj/arm_l.obj"/>
      </geometry>
    </visual>
    <collision>
      <origin rpy="0 0 0" xyz="0 0.0385 -0.02575"/>
      <geometry>
        <box size="0.0285 0.1045 0.08"/>
      </geometry>
    </collision>
    <inertial>
      <origin rpy="0 0 0" xyz="0 0.0385 -0.02575"/>
      <mass value="0.342"/>
      <inertia ixx="0.000493627125" ixy="0.0" ixz="0.0" iyy="0.000205549125" iyz="0.0" izz="0.00033437625000000003"/>
    </inertial>
  </link>
  <joint name="scissor_lf_joint" type="revolute">
    <parent link="arm_l"/>
    <child link="scissor_lf"/>
    <origin rpy="0 0 0" xyz="0 0.0265 -0.0545"/>
    <axis xyz="0 1 0"/>
    <limit effort="1000.0" lower="-3.1" upper="3.1" velocity="10.0"/>
    <dynamics damping="0.0" friction="0.0"/>
  </joint>
  <link name="scissor_lf">
    <visual>
      <origin rpy="0 0 0" xyz="0 0 0"/>
      <geometry>
        <mesh filename="package://kuroko_description/meshes/kuroko/obj/scissor_lf.obj"/>
      </geometry>
    </visual>
    <collision>
      <origin rpy="0 0 0" xyz="0.0043 0 -0.104"/>
      <geometry>
        <box size="0.01085 0.058 0.208"/>
      </geometry>
    </collision>
    <collision>
      <origin rpy="0 0 0" xyz="-0.0206 0 -0.201"/>
      <geometry>
        <box size="0.039 0.058 0.014"/>
      </geometry>
    </collision>
    <inertial>
      <origin rpy="0 0 0" xyz="0.0043 0 -0.104"/>
      <mass value="0.032"/>
      <inertia ixx="0.00012434133333333333" ixy="0.0" ixz="0.0" iyy="0.00012053333333333334" iyz="0.0" izz="1.4133333333333334e-05"/>
    </inertial>
  </link>
  <joint name="scissor_lr_joint" type="revolute">
    <parent link="arm_l"/>
    <child link="scissor_lr"/>
    <origin rpy="0 0 0" xyz="0 0.0265 -0.0545"/>
    <axis xyz="0 -1 0"/>
    <limit effort="1000.0" lower="-3.1" upper="3.1" velocity="10.0"/>
    <dynamics damping="0.0" friction="0.0"/>
  </joint>
  <link name="scissor_lr">
    <visual>
      <origin rpy="0 0 0" xyz="0 0 0"/>
      <geometry>
        <mesh filename="package://kuroko_description/meshes/kuroko/obj/scissor_lr.obj"/>
      </geometry>
    </visual>
    <collision>
      <origin rpy="0 0 0" xyz="-0.0043 0 -0.1"/>
      <geometry>
        <box size="0.01085 0.044 0.2"/>
      </geometry>
    </collision>
    <collision>
      <origin rpy="0 0 0" xyz="0.0206 0 -0.193"/>
      <geometry>
        <box size="0.039 0.044 0.014"/>
      </geometry>
    </collision>
    <inertial>
      <origin rpy="0 0 0" xyz="-0.0043 0 -0.1"/>
      <mass value="0.031"/>
      <inertia ixx="0.00010833466666666668" ixy="0.0" ixz="0.0" iyy="0.00010833466666666668" iyz="0.0" izz="1.0002666666666667e-05"/>
    </inertial>
  </link>
  <gazebo reference="shoulder_l_joint">
    <implicitSpringDamper>1</implicitSpringDamper>
  </gazebo>
  <transmission name="shoulder_l_joint_trans">
    <type>transmission_interface/SimpleTransmission</type>
    <joint name="shoulder_l_joint">
      <hardwareInterface>hardware_interface/PositionJointInterface</hardwareInterface>
    </joint>
    <actuator name="shoulder_l_joint_motor">
      <hardwareInterface>hardware_interface/PositionJointInterface</hardwareInterface>
      <mechanicalReduction>1</mechanicalReduction>
    </actuator>
  </transmission>
  <gazebo reference="shoulder_l">
    <kp>1000000.0</kp>
    <kd>100.0</kd>
    <mu1>0.0</mu1>
    <maxVel>10.0</maxVel>
    <minDepth>0.0001</minDepth>
    <maxContacts>6</maxContacts>
    <selfCollide>false</selfCollide>
    <dampingFactor>0</dampingFactor>
  </gazebo>
  <!-- Link conencts from body. Femoral first. -->
  <joint name="crotch_r_joint" type="revolute">
    <parent link="waist"/>
    <child link="crotch_r"/>
    <origin rpy="0 0 0" xyz="0.00125 0 -0.08425"/>
    <axis xyz="1 0 0"/>
    <limit effort="1000.0" lower="-3.1" upper="3.1" velocity="10.0"/>
    <dynamics damping="0.0" friction="0.0"/>
  </joint>
  <link name="crotch_r">
    <visual>
      <origin rpy="0 0 0" xyz="0 0 0"/>
      <geometry>
        <mesh filename="package://kuroko_description/meshes/kuroko/obj/crotch_r.obj"/>
      </geometry>
    </visual>
    <collision>
      <origin rpy="0 0 0" xyz="0 -0.0065 -0.004125"/>
      <geometry>
        <box size="0.092 0.041 0.03625"/>
      </geometry>
    </collision>
    <inertial>
      <origin rpy="0 0 0" xyz="0 -0.0065 -0.004125"/>
      <mass value="0.026"/>
      <inertia ixx="1e-05" ixy="0.0" ixz="0.0" iyy="2.118580208333333e-05" iyz="0.0" izz="2.198083333333333e-05"/>
    </inertial>
  </link>
  <joint name="thigh_r_01_joint" type="revolute">
    <parent link="crotch_r"/>
    <child link="thigh_r_01"/>
    <origin rpy="0 0 0" xyz="0 -0.027 0"/>
    <axis xyz="0 -1 0"/>
    <limit effort="1000.0" lower="-3.1" upper="3.1" velocity="10.0"/>
    <dynamics damping="0.0" friction="0.0"/>
  </joint>
  <link name="thigh_r_01">
    <visual>
      <origin rpy="0 0 0" xyz="0 0 0"/>
      <geometry>
        <mesh filename="package://kuroko_description/meshes/kuroko/obj/thigh_r_01.obj"/>
      </geometry>
    </visual>
    <collision>
      <origin rpy="0 0 0" xyz="-0.00175 -0.049 -0.015"/>
      <geometry>
        <box size="0.067 0.098 0.0585"/>
      </geometry>
    </collision>
    <inertial>
      <origin rpy="0 0 0" xyz="-0.00175 -0.049 -0.015"/>
      <mass value="0.478"/>
      <inertia ixx="0.0005188789583333333" ixy="0.0" ixz="0.0" iyy="0.0003151314583333334" iyz="0.0" izz="0.0005613711666666666"/>
    </inertial>
  </link>
  <joint name="thigh_r_02_joint" type="revolute">
    <parent link="thigh_r_01"/>
    <child link="thigh_r_02"/>
    <origin rpy="0 -0.785398163 0" xyz="0.015 -0.02925 -0.0305"/>
    <axis xyz="0 1 0"/>
    <limit effort="1000.0" lower="-3.1" upper="3.1" velocity="10.0"/>
    <dynamics damping="0.0" friction="0.0"/>
  </joint>
  <link name="thigh_r_02">
    <visual>
      <origin rpy="0 0 0" xyz="0 0 0"/>
      <geometry>
        <mesh filename="package://kuroko_description/meshes/kuroko/obj/thigh_r_02.obj"/>
      </geometry>
    </visual>
    <collision>
      <origin rpy="0 0 0" xyz="0 0 -0.05"/>
      <geometry>
        <box size="0.014 0.0445 0.114"/>
      </geometry>
    </collision>
    <inertial>
      <origin rpy="0 0 0" xyz="0 0 -0.05"/>
      <mass value="0.012"/>
      <inertia ixx="1.4976249999999999e-05" ixy="0.0" ixz="0.0" iyy="1.3192e-05" iyz="0.0" izz="1e-05"/>
    </inertial>
  </link>
  <joint name="thigh_r_03_joint" type="revolute">
    <parent link="thigh_r_01"/>
    <child link="thigh_r_03"/>
    <origin rpy="0 1.047197551 0" xyz="-0.0185 -0.02925 -0.0305"/>
    <axis xyz="0 1 0"/>
    <limit effort="1000.0" lower="-3.1" upper="3.1" velocity="10.0"/>
    <dynamics damping="0.0" friction="0.0"/>
  </joint>
  <link name="thigh_r_03">
    <visual>
      <origin rpy="0 0 0" xyz="0 0 0"/>
      <geometry>
        <mesh filename="package://kuroko_description/meshes/kuroko/obj/thigh_r_03.obj"/>
      </geometry>
    </visual>
    <collision>
      <origin rpy="0 0 0" xyz="-0.004745 0 -0.015"/>
      <geometry>
        <box size="0.02349 0.0445 0.044"/>
      </geometry>
    </collision>
    <inertial>
      <origin rpy="0 0 0" xyz="-0.004745 0 -0.015"/>
      <mass value="0.008"/>
      <inertia ixx="1e-05" ixy="0.0" ixz="0.0" iyy="1e-05" iyz="0.0" izz="1e-05"/>
    </inertial>
  </link>
  <joint name="thigh_r_04_joint" type="revolute">
    <parent link="thigh_r_01"/>
    <child link="thigh_r_04"/>
    <origin rpy="0 -0.785398163 0" xyz="-0.0185 -0.02925 -0.0305"/>
    <axis xyz="0 1 0"/>
    <limit effort="1000.0" lower="-3.1" upper="3.1" velocity="10.0"/>
    <dynamics damping="0.0" friction="0.0"/>
    <mimic joint="thigh_r_02_joint" multiplier="1" offset="0"/>
  </joint>
  <link name="thigh_r_04">
    <visual>
      <origin rpy="0 0 0" xyz="0 0 0"/>
      <geometry>
        <mesh filename="package://kuroko_description/meshes/kuroko/obj/thigh_r_04.obj"/>
      </geometry>
    </visual>
    <collision>
      <origin rpy="0 0 0" xyz="0 0 -0.05"/>
      <geometry>
        <box size="0.014 0.0345 0.114"/>
      </geometry>
    </collision>
    <inertial>
      <origin rpy="0 0 0" xyz="0 0 -0.05"/>
      <mass value="0.012"/>
      <inertia ixx="1.4186250000000002e-05" ixy="0.0" ixz="0.0" iyy="1.3192e-05" iyz="0.0" izz="1e-05"/>
    </inertial>
  </link>
  <joint name="thigh_r_05_mimic1" type="revolute">
    <parent link="thigh_r_03"/>
    <child link="thigh_r_05"/>
    <origin rpy="0 -1.832597551 0" xyz="0 0 -0.03"/>
    <axis xyz="0 1 0"/>
    <limit effort="1000.0" lower="-3.1" upper="3.1" velocity="10.0"/>
    <dynamics damping="0.0" friction="0.0"/>
    <mimic joint="thigh_r_03_joint" multiplier="-1" offset="0"/>
    <mimic joint="thigh_r_02_joint" multiplier="1" offset="0"/>
  </joint>
  <!-- <link name="thigh_r_05_mimic" />
		<joint name="thigh_r_05_mimic2" type="revolute">
			<parent link="thigh_r_05_mimic" />
			<child link="thigh_r_05" />
			<origin xyz="0 0 0" rpy="0 0 0" />
			<axis xyz="0 1 0" />
			<limit effort="1000.0" lower="-3.1" upper="3.1" velocity="10.0" />
			<dynamics damping="0.0" friction="0.0" />
			<mimic joint="thigh_r_02_joint" multiplier="1" offset="0" />
		</joint> -->
  <link name="thigh_r_05">
    <visual>
      <origin rpy="0 0 0" xyz="0 0 0"/>
      <geometry>
        <mesh filename="package://kuroko_description/meshes/kuroko/obj/thigh_r_05.obj"/>
      </geometry>
    </visual>
    <collision>
      <origin rpy="0 0 0" xyz="0 0 -0.05"/>
      <geometry>
        <box size="0.014 0.0285 0.114"/>
      </geometry>
    </collision>
    <inertial>
      <origin rpy="0 0 0" xyz="0 0 -0.05"/>
      <mass value="0.011"/>
      <inertia ixx="1.26575625e-05" ixy="0.0" ixz="0.0" iyy="1.2092666666666667e-05" iyz="0.0" izz="1e-05"/>
    </inertial>
  </link>
  <joint name="knee_r_joint" type="revolute">
    <parent link="thigh_r_02"/>
    <child link="knee_r"/>
    <origin rpy="0 0.785398163 0" xyz="0 0 -0.1"/>
    <axis xyz="0 1 0"/>
    <limit effort="1000.0" lower="-3.1" upper="3.1" velocity="10.0"/>
    <dynamics damping="0.0" friction="0.0"/>
    <mimic joint="thigh_r_02_joint" multiplier="-1" offset="0"/>
  </joint>
  <link name="knee_r">
    <visual>
      <origin rpy="0 0 0" xyz="0 0 0"/>
      <geometry>
        <mesh filename="package://kuroko_description/meshes/kuroko/obj/knee_r.obj"/>
      </geometry>
    </visual>
    <collision>
      <origin rpy="0 0 0" xyz="-0.01675 0 0"/>
      <geometry>
        <box size="0.0475 0.0505 0.014"/>
      </geometry>
    </collision>
    <inertial>
      <origin rpy="0 0 0" xyz="-0.01675 0 0"/>
      <mass value="0.007"/>
      <inertia ixx="1e-05" ixy="0.0" ixz="0.0" iyy="1e-05" iyz="0.0" izz="1e-05"/>
    </inertial>
  </link>
  <joint name="leg_r_01_joint" type="revolute">
    <parent link="knee_r"/>
    <child link="leg_r_01"/>
    <origin rpy="0 0.785398163 0" xyz="0 0 0"/>
    <axis xyz="0 1 0"/>
    <limit effort="1000.0" lower="-3.1" upper="3.1" velocity="10.0"/>
    <dynamics damping="0.0" friction="0.0"/>
    <mimic joint="thigh_r_03_joint" multiplier="1" offset="0"/>
  </joint>
  <link name="leg_r_01">
    <visual>
      <origin rpy="0 0 0" xyz="0 0 0"/>
      <geometry>
        <mesh filename="package://kuroko_description/meshes/kuroko/obj/leg_r_01.obj"/>
      </geometry>
    </visual>
    <collision>
      <origin rpy="0 0 0" xyz="0 0 -0.05"/>
      <geometry>
        <box size="0.014 0.0385 0.114"/>
      </geometry>
    </collision>
    <inertial>
      <origin rpy="0 0 0" xyz="0 0 -0.05"/>
      <mass value="0.013"/>
      <inertia ixx="1.5684770833333335e-05" ixy="0.0" ixz="0.0" iyy="1.4291333333333335e-05" iyz="0.0" izz="1e-05"/>
    </inertial>
  </link>
  <joint name="leg_r_02_joint" type="revolute">
    <parent link="knee_r"/>
    <child link="leg_r_02"/>
    <origin rpy="0 0.785398163 0" xyz="-0.0335 0 0"/>
    <axis xyz="0 1 0"/>
    <limit effort="1000.0" lower="-3.1" upper="3.1" velocity="10.0"/>
    <dynamics damping="0.0" friction="0.0"/>
    <mimic joint="thigh_r_03_joint" multiplier="1" offset="0"/>
  </joint>
  <link name="leg_r_02">
    <visual>
      <origin rpy="0 0 0" xyz="0 0 0"/>
      <geometry>
        <mesh filename="package://kuroko_description/meshes/kuroko/obj/leg_r_02.obj"/>
      </geometry>
    </visual>
    <collision>
      <origin rpy="0 0 0" xyz="0 0 -0.05"/>
      <geometry>
        <box size="0.014 0.0445 0.114"/>
      </geometry>
    </collision>
    <inertial>
      <origin rpy="0 0 0" xyz="0 0 -0.05"/>
      <mass value="0.016"/>
      <inertia ixx="1.9968333333333333e-05" ixy="0.0" ixz="0.0" iyy="1.7589333333333335e-05" iyz="0.0" izz="1e-05"/>
    </inertial>
  </link>
  <joint name="ankle_r_01_joint" type="revolute">
    <parent link="leg_r_01"/>
    <child link="ankle_r_01"/>
    <origin rpy="0 -0.785398163 0" xyz="0 0 -0.1"/>
    <axis xyz="0 1 0"/>
    <limit effort="1000.0" lower="-3.1" upper="3.1" velocity="10.0"/>
    <dynamics damping="0.0" friction="0.0"/>
    <mimic joint="thigh_r_03_joint" multiplier="-1" offset="0"/>
  </joint>
  <link name="ankle_r_01">
    <visual>
      <origin rpy="0 0 0" xyz="0 0 0"/>
      <geometry>
        <mesh filename="package://kuroko_description/meshes/kuroko/obj/ankle_r_01.obj"/>
      </geometry>
    </visual>
    <collision>
      <origin rpy="0 0 0" xyz="-0.0285 0 -0.013"/>
      <geometry>
        <box size="0.0855 0.0325 0.0465"/>
      </geometry>
    </collision>
    <inertial>
      <origin rpy="0 0 0" xyz="-0.0285 0 -0.013"/>
      <mass value="0.104"/>
      <inertia ixx="2.7893666666666667e-05" ixy="0.0" ixz="0.0" iyy="8.209500000000002e-05" iyz="0.0" izz="7.250966666666666e-05"/>
    </inertial>
  </link>
  <joint name="toe_r_01_joint" type="revolute">
    <parent link="ankle_r_01"/>
    <child link="toe_r_01"/>
    <origin rpy="0 0 0" xyz="-0.015 0 -0.025"/>
    <axis xyz="1 0 0"/>
    <limit effort="1000.0" lower="-3.1" upper="3.1" velocity="10.0"/>
    <dynamics damping="0.0" friction="0.0"/>
  </joint>
  <link name="toe_r_01">
    <visual>
      <origin rpy="0 0 0" xyz="0 0 0"/>
      <geometry>
        <mesh filename="package://kuroko_description/meshes/kuroko/obj/toe_r_01.obj"/>
      </geometry>
    </visual>
    <collision>
      <origin rpy="0 0 0" xyz="0 -0.009375 -0.01175"/>
      <geometry>
        <box size="0.0365 0.05375 0.043"/>
      </geometry>
    </collision>
    <inertial>
      <origin rpy="0 0 0" xyz="0 -0.009375 -0.01175"/>
      <mass value="0.136"/>
      <inertia ixx="5.3698041666666665e-05" ixy="0.0" ixz="0.0" iyy="3.6054166666666664e-05" iyz="0.0" izz="4.7841541666666664e-05"/>
    </inertial>
  </link>
  <joint name="toe_r_02_joint" type="revolute">
    <parent link="toe_r_01"/>
    <child link="toe_r_02"/>
    <origin rpy="0 0 0" xyz="0 0 -0.03825"/>
    <axis xyz="0 0 -1"/>
    <limit effort="1000.0" lower="-3.1" upper="3.1" velocity="10.0"/>
    <dynamics damping="0.0" friction="0.0"/>
  </joint>
  <link name="toe_r_02">
    <visual>
      <origin rpy="0 0 0" xyz="0 0 0"/>
      <geometry>
        <mesh filename="package://kuroko_description/meshes/kuroko/obj/toe_r_02.obj"/>
      </geometry>
    </visual>
    <collision>
      <origin rpy="0 0 0" xyz="0 0 -0.0025"/>
      <geometry>
        <box size="0.12 0.075 0.005"/>
      </geometry>
    </collision>
    <inertial>
      <origin rpy="0 0 0" xyz="0 0 -0.0025"/>
      <mass value="0.043"/>
      <inertia ixx="2.0245833333333332e-05" ixy="0.0" ixz="0.0" iyy="5.168958333333333e-05" iyz="0.0" izz="7.175625e-05"/>
    </inertial>
  </link>
  <gazebo>
    <joint name="thigh_r_05_joint" type="revolute">
      <parent>thigh_r_03</parent>
      <child>thigh_r_05</child>
      <pose>-0.03 0 0 0 0 0</pose>
      <axis>
        <xyz>0 1 0</xyz>
        <limit>
          <lower>-3.1</lower>
          <upper>3.1</upper>
        </limit>
        <dynamics>
          <spring_reference>0</spring_reference>
          <spring_stiffness>0</spring_stiffness>
        </dynamics>
        <use_parent_model_frame>1</use_parent_model_frame>
      </axis>
      <physics>
        <ode>
          <implicit_spring_damper>1</implicit_spring_damper>
          <cfm_damping>0</cfm_damping>
          <limit>
            <cfm>1e-7</cfm>
            <erp>0.8</erp>
          </limit>
        </ode>
      </physics>
    </joint>
  </gazebo>
  <gazebo reference="leg_r_joint01">
    <implicitSpringDamper>1</implicitSpringDamper>
  </gazebo>
  <transmission name="leg_r_joint01_trans">
    <type>transmission_interface/SimpleTransmission</type>
    <joint name="leg_r_joint01">
      <hardwareInterface>hardware_interface/PositionJointInterface</hardwareInterface>
    </joint>
    <actuator name="leg_r_joint01_motor">
      <hardwareInterface>hardware_interface/PositionJointInterface</hardwareInterface>
      <mechanicalReduction>1</mechanicalReduction>
    </actuator>
  </transmission>
  <gazebo reference="leg_r_joint02">
    <implicitSpringDamper>1</implicitSpringDamper>
  </gazebo>
  <transmission name="leg_r_joint02_trans">
    <type>transmission_interface/SimpleTransmission</type>
    <joint name="leg_r_joint02">
      <hardwareInterface>hardware_interface/PositionJointInterface</hardwareInterface>
    </joint>
    <actuator name="leg_r_joint02_motor">
      <hardwareInterface>hardware_interface/PositionJointInterface</hardwareInterface>
      <mechanicalReduction>1</mechanicalReduction>
    </actuator>
  </transmission>
  <gazebo reference="leg_r_joint03">
    <implicitSpringDamper>1</implicitSpringDamper>
  </gazebo>
  <transmission name="leg_r_joint03_trans">
    <type>transmission_interface/SimpleTransmission</type>
    <joint name="leg_r_joint03">
      <hardwareInterface>hardware_interface/PositionJointInterface</hardwareInterface>
    </joint>
    <actuator name="leg_r_joint03_motor">
      <hardwareInterface>hardware_interface/PositionJointInterface</hardwareInterface>
      <mechanicalReduction>1</mechanicalReduction>
    </actuator>
  </transmission>
  <gazebo reference="leg_r_joint04">
    <implicitSpringDamper>1</implicitSpringDamper>
  </gazebo>
  <transmission name="leg_r_joint04_trans">
    <type>transmission_interface/SimpleTransmission</type>
    <joint name="leg_r_joint04">
      <hardwareInterface>hardware_interface/PositionJointInterface</hardwareInterface>
    </joint>
    <actuator name="leg_r_joint04_motor">
      <hardwareInterface>hardware_interface/PositionJointInterface</hardwareInterface>
      <mechanicalReduction>1</mechanicalReduction>
    </actuator>
  </transmission>
  <gazebo reference="leg_r_joint05">
    <implicitSpringDamper>1</implicitSpringDamper>
  </gazebo>
  <gazebo reference="leg_r_joint06">
    <implicitSpringDamper>1</implicitSpringDamper>
  </gazebo>
  <gazebo reference="leg_r_joint07">
    <implicitSpringDamper>1</implicitSpringDamper>
  </gazebo>
  <gazebo reference="leg_r_joint08">
    <implicitSpringDamper>1</implicitSpringDamper>
  </gazebo>
  <gazebo reference="leg_r_joint09">
    <implicitSpringDamper>1</implicitSpringDamper>
  </gazebo>
  <gazebo reference="leg_r_joint10">
    <implicitSpringDamper>1</implicitSpringDamper>
  </gazebo>
  <gazebo reference="leg_r_joint11">
    <implicitSpringDamper>1</implicitSpringDamper>
  </gazebo>
  <transmission name="leg_r_joint11_trans">
    <type>transmission_interface/SimpleTransmission</type>
    <joint name="leg_r_joint11">
      <hardwareInterface>hardware_interface/PositionJointInterface</hardwareInterface>
    </joint>
    <actuator name="leg_r_joint11_motor">
      <hardwareInterface>hardware_interface/PositionJointInterface</hardwareInterface>
      <mechanicalReduction>1</mechanicalReduction>
    </actuator>
  </transmission>
  <gazebo reference="leg_r_joint12">
    <implicitSpringDamper>1</implicitSpringDamper>
  </gazebo>
  <transmission name="leg_r_joint12_trans">
    <type>transmission_interface/SimpleTransmission</type>
    <joint name="leg_r_joint12">
      <hardwareInterface>hardware_interface/PositionJointInterface</hardwareInterface>
    </joint>
    <actuator name="leg_r_joint12_motor">
      <hardwareInterface>hardware_interface/PositionJointInterface</hardwareInterface>
      <mechanicalReduction>1</mechanicalReduction>
    </actuator>
  </transmission>
  <gazebo reference="leg_r_ft_sensor_joint">
    <implicitSpringDamper>1</implicitSpringDamper>
  </gazebo>
  <gazebo reference="leg_r_link01">
    <kp>1000000.0</kp>
    <kd>100.0</kd>
    <mu1>0.0</mu1>
    <maxVel>10.0</maxVel>
    <minDepth>0.0001</minDepth>
    <maxContacts>6</maxContacts>
    <selfCollide>false</selfCollide>
    <dampingFactor>0</dampingFactor>
  </gazebo>
  <gazebo reference="leg_r_link02">
    <kp>1000000.0</kp>
    <kd>100.0</kd>
    <mu1>0.01</mu1>
    <maxVel>10.0</maxVel>
    <minDepth>0.0001</minDepth>
    <maxContacts>6</maxContacts>
    <selfCollide>false</selfCollide>
    <dampingFactor>0</dampingFactor>
  </gazebo>
  <gazebo reference="leg_r_link03">
    <kp>1000000.0</kp>
    <kd>100.0</kd>
    <mu1>0.0</mu1>
    <maxVel>10.0</maxVel>
    <minDepth>0.0001</minDepth>
    <maxContacts>6</maxContacts>
    <selfCollide>false</selfCollide>
    <dampingFactor>0</dampingFactor>
  </gazebo>
  <gazebo reference="leg_r_link04">
    <kp>1000000.0</kp>
    <kd>100.0</kd>
    <mu1>0.0</mu1>
    <maxVel>10.0</maxVel>
    <minDepth>0.0001</minDepth>
    <maxContacts>6</maxContacts>
    <selfCollide>false</selfCollide>
    <dampingFactor>0</dampingFactor>
  </gazebo>
  <gazebo reference="leg_r_link05">
    <kp>1000000.0</kp>
    <kd>100.0</kd>
    <mu1>0.0</mu1>
    <maxVel>10.0</maxVel>
    <minDepth>0.0001</minDepth>
    <maxContacts>6</maxContacts>
    <selfCollide>false</selfCollide>
    <dampingFactor>0</dampingFactor>
  </gazebo>
  <gazebo reference="leg_r_link06">
    <kp>1000000.0</kp>
    <kd>100.0</kd>
    <mu1>0.0</mu1>
    <maxVel>10.0</maxVel>
    <minDepth>0.0001</minDepth>
    <maxContacts>6</maxContacts>
    <selfCollide>false</selfCollide>
    <dampingFactor>0</dampingFactor>
  </gazebo>
  <gazebo reference="leg_r_link07">
    <kp>1000000.0</kp>
    <kd>100.0</kd>
    <mu1>0.01</mu1>
    <maxVel>10.0</maxVel>
    <minDepth>0.0001</minDepth>
    <maxContacts>6</maxContacts>
    <selfCollide>false</selfCollide>
    <dampingFactor>0</dampingFactor>
  </gazebo>
  <gazebo reference="leg_r_link08">
    <kp>1000000.0</kp>
    <kd>100.0</kd>
    <mu1>0.0</mu1>
    <maxVel>10.0</maxVel>
    <minDepth>0.0001</minDepth>
    <maxContacts>6</maxContacts>
    <selfCollide>false</selfCollide>
    <dampingFactor>0</dampingFactor>
  </gazebo>
  <gazebo reference="leg_r_link09">
    <kp>1000000.0</kp>
    <kd>100.0</kd>
    <mu1>0.0</mu1>
    <maxVel>10.0</maxVel>
    <minDepth>0.0001</minDepth>
    <maxContacts>6</maxContacts>
    <selfCollide>false</selfCollide>
    <dampingFactor>0</dampingFactor>
  </gazebo>
  <gazebo reference="leg_r_link10">
    <kp>1000000.0</kp>
    <kd>100.0</kd>
    <mu1>0.01</mu1>
    <maxVel>10.0</maxVel>
    <minDepth>0.0001</minDepth>
    <maxContacts>6</maxContacts>
    <selfCollide>false</selfCollide>
    <dampingFactor>0</dampingFactor>
  </gazebo>
  <gazebo reference="leg_r_link11">
    <kp>1000000.0</kp>
    <kd>100.0</kd>
    <mu1>0.0</mu1>
    <maxVel>10.0</maxVel>
    <minDepth>0.0001</minDepth>
    <maxContacts>6</maxContacts>
    <selfCollide>false</selfCollide>
    <dampingFactor>0</dampingFactor>
  </gazebo>
  <gazebo reference="leg_r_link12_1">
    <kp>1000000.0</kp>
    <kd>100.0</kd>
    <mu1>0.0</mu1>
    <maxVel>10.0</maxVel>
    <minDepth>0.0001</minDepth>
    <maxContacts>6</maxContacts>
    <selfCollide>false</selfCollide>
    <dampingFactor>0</dampingFactor>
  </gazebo>
  <gazebo reference="leg_r_link12_2">
    <kp>1000000.0</kp>
    <kd>100.0</kd>
    <mu1>0.5</mu1>
    <maxVel>10.0</maxVel>
    <minDepth>0.0001</minDepth>
    <maxContacts>6</maxContacts>
    <selfCollide>false</selfCollide>
    <dampingFactor>0</dampingFactor>
  </gazebo>
  <!-- 
    <xacro:leg_l_xacro/>
    <xacro:leg_l_gazebo gazebo_hw_interface="${gazebo_hw_interface}"/>-->
  <gazebo>
    <plugin filename="libgazebo_dc_motor.so" name="gazebo_ros_control">
      <robotNamespace>kuroko</robotNamespace>
      <robotSimType>gazebo_dc_motor/DefaultRobotHWSim</robotSimType>
      <legacyModeNS>false</legacyModeNS>
    </plugin>
  </gazebo>
  <!-- <xacro:imu_xacro model_mode="$(arg model_mode)"/> -->
  <!-- <xacro:urg_xacro firame_id="arm_r_urg_link" topic_name="/sensor/urg/right/scan_raw"
  sensor_name="urg_right"/> -->
  <!-- <xacro:urg_xacro firame_id="arm_l_urg_link" topic_name="/sensor/urg/left/scan_raw"
  sensor_name="urg_left"/> -->
</robot>
