<?xml version="1.0"?>
<robot xmlns:xacro="http://www.ros.org/wiki/xacro">
	<xacro:macro name="arm_r_xacro">
		<!-- Link conencts from body. Shoulder first. -->
		<joint name="shoulder_r_joint" type="revolute">
			<parent link="chest" />
			<child link="shoulder_r" />
			<origin xyz="0 -0.082 0.05075" rpy="0 0 0" />
			<axis xyz="0 -1 0" />
			<limit effort="1000.0" lower="-3.1" upper="3.1" velocity="10.0" />
			<dynamics damping="0.0" friction="0.0" />
		</joint>
		<link name="shoulder_r">
			<visual>
				<origin xyz="0 0 0" rpy="0 0 0" />
				<geometry>
					<mesh filename="package://kuroko_description/meshes/kuroko/obj/shoulder_r.obj" />
				</geometry>
			</visual>
			<xacro:box_collision xyz="0 -0.0205 0" rpy="0 0 0" size="0.053 0.041 0.04" />
			<xacro:box_inertial xyz="0 -0.0205 0" rpy="0 0 0" size="0.053 0.041 0.04" mass="0.022" />
		</link>
		<joint name="arm_r_joint" type="revolute">
			<parent link="shoulder_r" />
			<child link="arm_r" />
			<origin xyz="0 -0.028 0" rpy="0 0 0" />
			<axis xyz="-1 0 0" />
			<limit effort="1000.0" lower="-3.1" upper="3.1" velocity="10.0" />
			<dynamics damping="0.0" friction="0.0" />
		</joint>
		<link name="arm_r">
			<visual>
				<origin xyz="0 0 0" rpy="0 0 0" />
				<geometry>
					<mesh filename="package://kuroko_description/meshes/kuroko/obj/arm_r.obj" />
				</geometry>
			</visual>
			<xacro:box_collision xyz="0 -0.0385 -0.02575" rpy="0 0 0" size="0.044 0.1045 0.085" />
			<xacro:box_inertial xyz="0 -0.0385 -0.02575" rpy="0 0 0" size="0.044 0.1045 0.085"
				mass="0.342" />
		</link>
		<joint name="scissor_rf_joint" type="revolute">
			<parent link="arm_r" />
			<child link="scissor_rf" />
			<origin xyz="0 -0.02575 -0.057" rpy="0 0 0" />
			<axis xyz="0 -1 0" />
			<limit effort="1000.0" lower="-3.1" upper="3.1" velocity="10.0" />
			<dynamics damping="0.0" friction="0.0" />
		</joint>
		<link name="scissor_rf">
			<visual>
				<origin xyz="0 0 0" rpy="0 0 0" />
				<geometry>
					<mesh filename="package://kuroko_description/meshes/kuroko/obj/scissor_rf.obj" />
				</geometry>
			</visual>
			<xacro:box_collision xyz="0.0043 0 -0.104" rpy="0 0 0" size="0.01085 0.058 0.208" />
			<xacro:box_collision xyz="-0.0206 0 -0.201" rpy="0 0 0" size="0.039 0.058 0.014" />
			<xacro:box_inertial xyz="0.0043 0 -0.104" rpy="0 0 0" size="0.044 0.058 0.208" mass="0.032" />
		</link>
		<joint name="scissor_rr_joint" type="revolute">
			<parent link="arm_r" />
			<child link="scissor_rr" />
			<origin xyz="0 -0.02575 -0.057" rpy="0 0 0" />
			<axis xyz="0 1 0" />
			<limit effort="1000.0" lower="-3.1" upper="3.1" velocity="10.0" />
			<dynamics damping="0.0" friction="0.0" />
		</joint>
		<link name="scissor_rr">
			<visual>
				<origin xyz="0 0 0" rpy="0 0 0" />
				<geometry>
					<mesh filename="package://kuroko_description/meshes/kuroko/obj/scissor_rr.obj" />
				</geometry>
			</visual>
			<xacro:box_collision xyz="-0.0043 0 -0.1" rpy="0 0 0" size="0.01085 0.044 0.2" />
			<xacro:box_collision xyz="0.0206 0 -0.193" rpy="0 0 0" size="0.039 0.044 0.014" />
			<xacro:box_inertial xyz="-0.0043 0 -0.1" rpy="0 0 0" size="0.044 0.044 0.2" mass="0.031" />
		</link>
	</xacro:macro>
</robot>