<?xml version="1.0"?>
<robot xmlns:xacro="http://www.ros.org/wiki/xacro">
	<xacro:macro name="arm_l_xacro">
		<!-- Link conencts from body. Shoulder first. -->
		<joint name="shoulder_l_joint" type="revolute">
			<parent link="chest" />
			<child link="shoulder_l" />
			<origin xyz="0 0.108 0.01275" rpy="0 0 0" />
			<axis xyz="0 1 0" />
			<limit effort="1000.0" lower="-3.1" upper="3.1" velocity="10.0" />
			<dynamics damping="0.0" friction="0.0" />
		</joint>
		<link name="shoulder_l">
			<visual>
				<origin xyz="0 0 0" rpy="0 0 0" />
				<geometry>
					<mesh filename="package://kuroko_description/meshes/kuroko/obj/shoulder_l.obj" />
				</geometry>
			</visual>
			<xacro:box_collision xyz="0 0.0205 0" rpy="0 0 0" size="0.042 0.041 0.04" />
			<xacro:box_inertial xyz="0 0.0205 0" rpy="0 0 0" size="0.042 0.041 0.04" mass="0.022" />
		</link>
		<joint name="arm_l_joint" type="revolute">
			<parent link="shoulder_l" />
			<child link="arm_l" />
			<origin xyz="0 0.028 0" rpy="0 0 0" />
			<axis xyz="-1 0 0" />
			<limit effort="1000.0" lower="-3.1" upper="3.1" velocity="10.0" />
			<dynamics damping="0.0" friction="0.0" />
		</joint>
		<link name="arm_l">
			<visual>
				<origin xyz="0 0 0" rpy="0 0 0" />
				<geometry>
					<mesh filename="package://kuroko_description/meshes/kuroko/obj/arm_l.obj" />
				</geometry>
			</visual>
			<xacro:box_collision xyz="0 0.0385 -0.02575" rpy="0 0 0" size="0.0285 0.1045 0.08" />
			<xacro:box_inertial xyz="0 0.0385 -0.02575" rpy="0 0 0" size="0.0285 0.1045 0.08" mass="0.342" />
		</link>
		<joint name="scissor_lf_joint" type="revolute">
			<parent link="arm_l" />
			<child link="scissor_lf" />
			<origin xyz="0 0.0265 -0.0545" rpy="0 0 0" />
			<axis xyz="0 1 0" />
			<limit effort="1000.0" lower="-3.1" upper="3.1" velocity="10.0" />
			<dynamics damping="0.0" friction="0.0" />
		</joint>
		<link name="scissor_lf">
			<visual>
				<origin xyz="0 0 0" rpy="0 0 0" />
				<geometry>
					<mesh filename="package://kuroko_description/meshes/kuroko/obj/scissor_lf.obj" />
				</geometry>
			</visual>
			<xacro:box_collision xyz="0.0043 0 -0.104" rpy="0 0 0" size="0.01085 0.058 0.208" />
			<xacro:box_collision xyz="-0.0206 0 -0.201" rpy="0 0 0" size="0.039 0.058 0.014" />
			<xacro:box_inertial xyz="0.0043 0 -0.104" rpy="0 0 0" size="0.044 0.058 0.208" mass="0.032" />
		</link>
		<joint name="scissor_lr_joint" type="revolute">
			<parent link="arm_l" />
			<child link="scissor_lr" />
			<origin xyz="0 0.0265 -0.0545" rpy="0 0 0" />
			<axis xyz="0 -1 0" />
			<limit effort="1000.0" lower="-3.1" upper="3.1" velocity="10.0" />
			<dynamics damping="0.0" friction="0.0" />
		</joint>
		<link name="scissor_lr">
			<visual>
				<origin xyz="0 0 0" rpy="0 0 0" />
				<geometry>
					<mesh filename="package://kuroko_description/meshes/kuroko/obj/scissor_lr.obj" />
				</geometry>
			</visual>
			<xacro:box_collision xyz="-0.0043 0 -0.1" rpy="0 0 0" size="0.01085 0.044 0.2" />
			<xacro:box_collision xyz="0.0206 0 -0.193" rpy="0 0 0" size="0.039 0.044 0.014" />
			<xacro:box_inertial xyz="-0.0043 0 -0.1" rpy="0 0 0" size="0.044 0.044 0.2" mass="0.031" />
		</link>
	</xacro:macro>
</robot>