<?xml version="1.0"?>
<robot xmlns:xacro="http://www.ros.org/wiki/xacro">
	<xacro:macro name="leg_r_xacro">
		<!-- Link conencts from body. Femoral first. -->
		<joint name="crotch_r_joint" type="revolute">
			<parent link="waist" />
			<child link="crotch_r" />
			<origin xyz="0.00125 0 -0.08425" rpy="0 0 0" />
			<axis xyz="1 0 0" />
			<limit effort="1000.0" lower="-3.1" upper="3.1" velocity="10.0" />
			<dynamics damping="0.0" friction="0.0" />
		</joint>
		<link name="crotch_r">
			<visual>
				<origin xyz="0 0 0" rpy="0 0 0" />
				<geometry>
					<mesh filename="package://kuroko_description/meshes/kuroko/obj/crotch_r.obj" />
				</geometry>
			</visual>
			<xacro:box_collision xyz="0 -0.0065 -0.004125" rpy="0 0 0" size="0.092 0.041 0.03625" />
			<xacro:box_inertial xyz="0 -0.0065 -0.004125" rpy="0 0 0" size="0.092 0.041 0.03625"
				mass="0.026" />
		</link>
		<joint name="thigh_r_01_joint" type="revolute">
			<parent link="crotch_r" />
			<child link="thigh_r_01" />
			<origin xyz="0 -0.027 0" rpy="0 0 0" />
			<axis xyz="0 -1 0" />
			<limit effort="1000.0" lower="-3.1" upper="3.1" velocity="10.0" />
			<dynamics damping="0.0" friction="0.0" />
		</joint>
		<link name="thigh_r_01">
			<visual>
				<origin xyz="0 0 0" rpy="0 0 0" />
				<geometry>
					<mesh filename="package://kuroko_description/meshes/kuroko/obj/thigh_r_01.obj" />
				</geometry>
			</visual>
			<xacro:box_collision xyz="-0.00175 -0.049 -0.015" rpy="0 0 0" size="0.067 0.098 0.0625" />
			<xacro:box_inertial xyz="-0.00175 -0.049 -0.015" rpy="0 0 0" size="0.067 0.098 0.0625"
				mass="0.484" />
		</link>
		<joint name="thigh_r_02_joint" type="revolute">
			<parent link="thigh_r_01" />
			<child link="thigh_r_02" />
			<origin xyz="0.015 -0.02925 -0.0305" rpy="0 0 0" />
			<axis xyz="0 1 0" />
			<limit effort="1000.0" lower="-3.1" upper="3.1" velocity="10.0" />
			<dynamics damping="0.0" friction="0.0" />
		</joint>
		<link name="thigh_r_02">
			<visual>
				<origin xyz="0 0 0" rpy="0 0 0" />
				<geometry>
					<mesh filename="package://kuroko_description/meshes/kuroko/obj/thigh_r_02.obj" />
				</geometry>
			</visual>
			<xacro:box_collision xyz="0 0 -0.05" rpy="0 0 0" size="0.014 0.0445 0.114" />
			<xacro:box_inertial xyz="0 0 -0.05" rpy="0 0 0" size="0.014 0.0445 0.114" mass="0.011" />
		</link>
		<joint name="thigh_r_03_joint" type="revolute">
			<parent link="thigh_r_01" />
			<child link="thigh_r_03" />
			<origin xyz="-0.015 -0.02925 -0.0305" rpy="0 0 0" />
			<axis xyz="0 1 0" />
			<limit effort="1000.0" lower="-3.1" upper="3.1" velocity="10.0" />
			<dynamics damping="0.0" friction="0.0" />
		</joint>
		<link name="thigh_r_03">
			<visual>
				<origin xyz="0 0 0" rpy="0 0 0" />
				<geometry>
					<mesh filename="package://kuroko_description/meshes/kuroko/obj/thigh_r_03.obj" />
				</geometry>
			</visual>
			<xacro:box_collision xyz="-0.004745 0 -0.015" rpy="0 0 0" size="0.02349 0.0445 0.044" />
			<xacro:box_inertial xyz="-0.004745 0 -0.015" rpy="0 0 0" size="0.02349 0.0445 0.044"
				mass="0.011" />
		</link>
		<joint name="thigh_r_04_joint" type="revolute">
			<parent link="thigh_r_01" />
			<child link="thigh_r_04" />
			<origin xyz="-0.015 -0.02925 -0.0305" rpy="0 0 0" />
			<axis xyz="0 1 0" />
			<limit effort="1000.0" lower="-3.1" upper="3.1" velocity="10.0" />
			<dynamics damping="0.0" friction="0.0" />
			<mimic joint="thigh_r_02_joint" multiplier="1" offset="0"/>
		</joint>
		<link name="thigh_r_04">
			<visual>
				<origin xyz="0 0 0" rpy="0 0 0" />
				<geometry>
					<mesh filename="package://kuroko_description/meshes/kuroko/obj/thigh_r_04.obj" />
				</geometry>
			</visual>
			<xacro:box_collision xyz="0 0 -0.05" rpy="0 0 0" size="0.014 0.0345 0.114" />
			<xacro:box_inertial xyz="0 0 -0.05" rpy="0 0 0" size="0.014 0.0345 0.114" mass="0.011" />
		</link>

	</xacro:macro>

</robot>